<?xml version="1.0" ?>
<robot name="robot_arm_3d" xmlns:xacro="http://ros.org/wiki/xacro">
    <!-- Material/Colors -->
    <material name="omni/Blue">
        <color rgba="0 0 0.8 1"/>
    </material>
    <material name="omni/Yellow">
        <color rgba="1 1 0 1"/>
    </material>
    <material name="omni/LightGrey">
        <color rgba="0.6 0.6 0.6 1"/>
    </material>

    <!-- Links/Joints -->
    <link name="base_point">
        <inertial>
            <origin rpy="0 0 0" xyz="0 0 0"/>
            <mass value="1e-8"/>
            <inertia ixx="1e-12" ixy="0" ixz="0" iyy="1e-12" iyz="0" izz="1e-12"/>
        </inertial>
    </link>

    <joint name="base_point-base" type="fixed">
        <origin rpy="0 0 0" xyz="0 0 0"/>
        <parent link="base_point"/>
        <child link="base"/>
    </joint>

    <link name="base">
        <visual>
            <origin rpy="0 0 0" xyz="0 0 0.01"/>
            <geometry>
                <box size="0.2 0.2 0.02"/>
            </geometry>
            <material name="omni/Blue"/>
        </visual>

        <collision>
            <origin rpy="0 0 0" xyz="0 0 0.01"/>
            <geometry>
                <box size="0.2 0.2 0.02"/>
            </geometry>
        </collision>

        <inertial>
            <origin rpy="0 0 0" xyz="0 0 0.01"/>
            <mass value="1"/>
            <inertia ixx="0.0835416666667" ixy="0" ixz="0" iyy="0.0834680033333" iyz="0" izz="0.000343003333333"/>
        </inertial>
    </link>

    <joint name="base-base_link" type="revolute">
        <parent link="base"/>
        <child link="base_link"/>
        <limit effort="2.5" velocity="10.0"/>
        <origin rpy="0 0 0" xyz="0 0 0.02"/>
        <axis xyz="0 0 1"/>
        <dynamics damping="0.2"/>
    </joint>

    <link name="base_link">
        <visual>
            <origin rpy="0 0 0" xyz="0 0 0.05"/>
            <geometry>
                <cylinder radius="0.05" length="0.1"/>
            </geometry>
            <material name="omni/Yellow"/>
        </visual>

        <!--<collision>
            <origin rpy="0 0 0" xyz="0 0 0.05"/>
            <geometry>
                <cylinder radius="0.05" length="0.1"/>
            </geometry>
        </collision>-->

        <inertial>
            <origin rpy="0 0 0" xyz="0 0 0.05"/>
            <mass value="0.2"/>
            <inertia ixx="0.000267245666667" ixy="0" ixz="0" iyy="0.000435483" iyz="0" izz="0.000267245666667"/>
        </inertial>
    </link>
    
    <joint name="base_link-link_1" type="revolute">
        <parent link="base_link"/>
        <child link="link_1"/>
        <limit effort="2.5" velocity="10.0"/>
        <origin rpy="0 0 0" xyz="0 0 0.1"/>
        <axis xyz="0 1 0"/>
        <dynamics damping="0.2"/>
    </joint>

    <link name="link_1">
        <visual>
            <origin rpy="0 0 0" xyz="0 0 0.2"/>
            <geometry>
                <box size="0.015 0.02 0.4"/>
            </geometry>
            <material name="omni/Blue"/>
        </visual>

        <collision>
            <origin rpy="0 0 0" xyz="0 0 0.2"/>
            <geometry>
                <box size="0.015 0.02 0.4"/>
            </geometry>
        </collision>

        <inertial>
            <origin rpy="0 0 0" xyz="0 0 0.2"/>
            <mass value="1"/>
            <inertia ixx="0.0835416666667" ixy="0" ixz="0" iyy="0.0834680033333" iyz="0" izz="0.000343003333333"/>
        </inertial>
    </link>

    <joint name="link_1-link_2" type="revolute">
        <parent link="link_1"/>
        <child link="link_2"/>
        <limit effort="2.5" velocity="10.0"/>
        <origin rpy="0 0 0" xyz="0 0 0.4"/>
        <axis xyz="0 1 0"/>
        <dynamics damping="0.2"/>
    </joint>

    <link name="link_2">
        <visual>
            <origin rpy="0 0 0" xyz="0 0 0.15"/>
            <geometry>
                <box size="0.015 0.02 0.3"/>
            </geometry>
            <material name="omni/Yellow"/>
        </visual>

        <collision>
            <origin rpy="0 0 0" xyz="0 0 0.15"/>
            <geometry>
                <box size="0.015 0.02 0.3"/>
            </geometry>
        </collision>

        <inertial>
            <origin rpy="0 0 0" xyz="0 0 0.15"/>
            <mass value="1"/>
            <inertia ixx="0.0835416666667" ixy="0" ixz="0" iyy="0.0834680033333" iyz="0" izz="0.000343003333333"/>
        </inertial>
    </link>

    <joint name="link_2-link_3" type="revolute">
        <parent link="link_2"/>
        <child link="link_3"/>
        <limit effort="2.5" velocity="10.0"/>
        <origin rpy="0 0 0" xyz="0 0 0.3"/>
        <axis xyz="0 1 0"/>
        <dynamics damping="0.2"/>
    </joint>

    <link name="link_3">
        <visual>
            <origin rpy="0 0 0" xyz="0 0 0.0675"/>
            <geometry>
                <box size="0.015 0.02 0.135"/>
            </geometry>
            <material name="omni/LightGrey"/>
        </visual>

        <collision>
            <origin rpy="0 0 0" xyz="0 0 0.0675"/>
            <geometry>
                <box size="0.015 0.02 0.135"/>
            </geometry>
        </collision>

        <inertial>
            <origin rpy="0 0 0" xyz="0 0 0.0675"/>
            <mass value="1"/>
            <inertia ixx="0.0835416666667" ixy="0" ixz="0" iyy="0.0834680033333" iyz="0" izz="0.000343003333333"/>
        </inertial>
    </link>

    <joint name="link_3-gripper_base" type="revolute">
        <parent link="link_3"/>
        <child link="gripper_base"/>
        <limit effort="2.5" velocity="10.0"/>
        <origin rpy="0 0 0" xyz="0 0 0.135"/>
        <axis xyz="0 1 0"/>
        <dynamics damping="0.2"/>
    </joint>

    <link name="gripper_base">
        <visual>
            <origin rpy="0 0 0" xyz="0 0 0.0075"/>
            <geometry>
                <box size="0.015 0.04 0.015"/>
            </geometry>
            <material name="omni/Blue"/>
        </visual>

        <collision>
            <origin rpy="0 0 0" xyz="0 0 0.0075"/>
            <geometry>
                <box size="0.04 0.015 0.015"/>
            </geometry>
        </collision>

        <inertial>
            <origin rpy="0 0 0" xyz="0 0 0.0075"/>
            <mass value="1"/>
            <inertia ixx="0.0835416666667" ixy="0" ixz="0" iyy="0.0834680033333" iyz="0" izz="0.000343003333333"/>
        </inertial>
    </link>

    <joint name="gripper_base-right_grip" type="revolute">
        <parent link="gripper_base"/>
        <child link="right_grip"/>
        <limit effort="2.5" velocity="10.0"/>
        <origin rpy="0 0 0" xyz="0 0 0.015"/>
        <axis xyz="1 0 0"/>
        <dynamics damping="0.2"/>
    </joint>

    <link name="right_grip">
        <visual>
            <origin rpy="0 0 0" xyz="0 0.015 0.01"/>
            <geometry>
                <box size="0.015 0.005 0.04"/>
            </geometry>
            <material name="omni/Blue"/>
        </visual>

        <collision>
            <origin rpy="0 0 0" xyz="0 0.015 0.0075"/>
            <geometry>
                <box size="0.015 0.005 0.04"/>
            </geometry>
        </collision>

        <inertial>
            <origin rpy="0 0 0" xyz="0 0.015 0.0075"/>
            <mass value="1"/>
            <inertia ixx="0.0835416666667" ixy="0" ixz="0" iyy="0.0834680033333" iyz="0" izz="0.000343003333333"/>
        </inertial>
    </link>

    <joint name="gripper_base-left_grip" type="revolute">
        <parent link="gripper_base"/>
        <child link="left_grip"/>
        <limit effort="2.5" velocity="10.0"/>
        <origin rpy="0 0 0" xyz="0 0 0.015"/>
        <axis xyz="1 0 0"/>
        <dynamics damping="0.2"/>
    </joint>

    <link name="left_grip">
        <visual>
            <origin rpy="0 0 0" xyz="0 -0.015 0.01"/>
            <geometry>
                <box size="0.015 0.005 0.04"/>
            </geometry>
            <material name="omni/Blue"/>
        </visual>

        <collision>
            <origin rpy="0 0 0" xyz="0 -0.015 0.0075"/>
            <geometry>
                <box size="0.015 0.005 0.04"/>
            </geometry>
        </collision>

        <inertial>
            <origin rpy="0 0 0" xyz="0 -0.015 0.0075"/>
            <mass value="1"/>
            <inertia ixx="0.0835416666667" ixy="0" ixz="0" iyy="0.0834680033333" iyz="0" izz="0.000343003333333"/>
        </inertial>
    </link>

    <joint name="gripper_base-end" type="fixed">
        <parent link="gripper_base"/>
        <child link="end"/>
        <origin rpy="0 0 0" xyz="0 0 0.015"/>
    </joint>

    <link name="end">
        <inertial>
            <origin rpy="0 0 0" xyz="0 0 0"/>
            <mass value="1e-8"/>
            <inertia ixx="1e-12" ixy="0" ixz="0" iyy="1e-12" iyz="0" izz="1e-12"/>
        </inertial>
    </link>

    
</robot>
